Workbook

Sheet SUMMARY
A1: Master coverage summary
A2: Counts update from the MASTER sheet. Generated 2026-10-31. "Concept covered?" is measured by comparing each item's distinctive terms with the book text (see LEGEND).
A4: Source | B4: Items | C4: Covered | D4: Partly covered | E4: Not covered | F4: Not measured | G4: Excluded by you | H4: No teaching content | I4: Not applicable | J4: Measurable items | K4: % Covered (of measurable) | L4: % Covered or partly
A5: Course repo file | B5: =COUNTIFS(MASTER!$B:$B,$A5) -> 464 | C5: =COUNTIFS(MASTER!$B:$B,$A5,MASTER!$H:$H,C$4) -> 225 | D5: =COUNTIFS(MASTER!$B:$B,$A5,MASTER!$H:$H,D$4) -> 27 | E5: =COUNTIFS(MASTER!$B:$B,$A5,MASTER!$H:$H,E$4) -> 4 | F5: =COUNTIFS(MASTER!$B:$B,$A5,MASTER!$H:$H,F$4) -> 0 | G5: =COUNTIFS(MASTER!$B:$B,$A5,MASTER!$H:$H,G$4) -> 67 | H5: =COUNTIFS(MASTER!$B:$B,$A5,MASTER!$H:$H,H$4) -> 141 | I5: =COUNTIFS(MASTER!$B:$B,$A5,MASTER!$H:$H,I$4) -> 0 | J5: =C5+D5+E5+F5 -> 256 | K5: =IF(J5=0,0,C5/J5) -> 0.87890625 | L5: =IF(J5=0,0,(C5+D5)/J5) -> 0.984375
A6: LangChain docs | B6: =COUNTIFS(MASTER!$B:$B,$A6) -> 196 | C6: =COUNTIFS(MASTER!$B:$B,$A6,MASTER!$H:$H,C$4) -> 39 | D6: =COUNTIFS(MASTER!$B:$B,$A6,MASTER!$H:$H,D$4) -> 10 | E6: =COUNTIFS(MASTER!$B:$B,$A6,MASTER!$H:$H,E$4) -> 1 | F6: =COUNTIFS(MASTER!$B:$B,$A6,MASTER!$H:$H,F$4) -> 0 | G6: =COUNTIFS(MASTER!$B:$B,$A6,MASTER!$H:$H,G$4) -> 26 | H6: =COUNTIFS(MASTER!$B:$B,$A6,MASTER!$H:$H,H$4) -> 3 | I6: =COUNTIFS(MASTER!$B:$B,$A6,MASTER!$H:$H,I$4) -> 117 | J6: =C6+D6+E6+F6 -> 50 | K6: =IF(J6=0,0,C6/J6) -> 0.78 | L6: =IF(J6=0,0,(C6+D6)/J6) -> 0.98
A7: MCP docs | B7: =COUNTIFS(MASTER!$B:$B,$A7) -> 100 | C7: =COUNTIFS(MASTER!$B:$B,$A7,MASTER!$H:$H,C$4) -> 48 | D7: =COUNTIFS(MASTER!$B:$B,$A7,MASTER!$H:$H,D$4) -> 44 | E7: =COUNTIFS(MASTER!$B:$B,$A7,MASTER!$H:$H,E$4) -> 7 | F7: =COUNTIFS(MASTER!$B:$B,$A7,MASTER!$H:$H,F$4) -> 0 | G7: =COUNTIFS(MASTER!$B:$B,$A7,MASTER!$H:$H,G$4) -> 0 | H7: =COUNTIFS(MASTER!$B:$B,$A7,MASTER!$H:$H,H$4) -> 1 | I7: =COUNTIFS(MASTER!$B:$B,$A7,MASTER!$H:$H,I$4) -> 0 | J7: =C7+D7+E7+F7 -> 99 | K7: =IF(J7=0,0,C7/J7) -> 0.48484848 | L7: =IF(J7=0,0,(C7+D7)/J7) -> 0.92929293
A8: Pydantic docs | B8: =COUNTIFS(MASTER!$B:$B,$A8) -> 56 | C8: =COUNTIFS(MASTER!$B:$B,$A8,MASTER!$H:$H,C$4) -> 13 | D8: =COUNTIFS(MASTER!$B:$B,$A8,MASTER!$H:$H,D$4) -> 25 | E8: =COUNTIFS(MASTER!$B:$B,$A8,MASTER!$H:$H,E$4) -> 12 | F8: =COUNTIFS(MASTER!$B:$B,$A8,MASTER!$H:$H,F$4) -> 0 | G8: =COUNTIFS(MASTER!$B:$B,$A8,MASTER!$H:$H,G$4) -> 0 | H8: =COUNTIFS(MASTER!$B:$B,$A8,MASTER!$H:$H,H$4) -> 5 | I8: =COUNTIFS(MASTER!$B:$B,$A8,MASTER!$H:$H,I$4) -> 1 | J8: =C8+D8+E8+F8 -> 50 | K8: =IF(J8=0,0,C8/J8) -> 0.26 | L8: =IF(J8=0,0,(C8+D8)/J8) -> 0.76
A9: Meridian slides | B9: =COUNTIFS(MASTER!$B:$B,$A9) -> 40 | C9: =COUNTIFS(MASTER!$B:$B,$A9,MASTER!$H:$H,C$4) -> 26 | D9: =COUNTIFS(MASTER!$B:$B,$A9,MASTER!$H:$H,D$4) -> 13 | E9: =COUNTIFS(MASTER!$B:$B,$A9,MASTER!$H:$H,E$4) -> 0 | F9: =COUNTIFS(MASTER!$B:$B,$A9,MASTER!$H:$H,F$4) -> 0 | G9: =COUNTIFS(MASTER!$B:$B,$A9,MASTER!$H:$H,G$4) -> 1 | H9: =COUNTIFS(MASTER!$B:$B,$A9,MASTER!$H:$H,H$4) -> 0 | I9: =COUNTIFS(MASTER!$B:$B,$A9,MASTER!$H:$H,I$4) -> 0 | J9: =C9+D9+E9+F9 -> 39 | K9: =IF(J9=0,0,C9/J9) -> 0.66666667 | L9: =IF(J9=0,0,(C9+D9)/J9) -> 1
A10: Craft page | B10: =COUNTIFS(MASTER!$B:$B,$A10) -> 21 | C10: =COUNTIFS(MASTER!$B:$B,$A10,MASTER!$H:$H,C$4) -> 13 | D10: =COUNTIFS(MASTER!$B:$B,$A10,MASTER!$H:$H,D$4) -> 0 | E10: =COUNTIFS(MASTER!$B:$B,$A10,MASTER!$H:$H,E$4) -> 2 | F10: =COUNTIFS(MASTER!$B:$B,$A10,MASTER!$H:$H,F$4) -> 0 | G10: =COUNTIFS(MASTER!$B:$B,$A10,MASTER!$H:$H,G$4) -> 0 | H10: =COUNTIFS(MASTER!$B:$B,$A10,MASTER!$H:$H,H$4) -> 6 | I10: =COUNTIFS(MASTER!$B:$B,$A10,MASTER!$H:$H,I$4) -> 0 | J10: =C10+D10+E10+F10 -> 15 | K10: =IF(J10=0,0,C10/J10) -> 0.86666667 | L10: =IF(J10=0,0,(C10+D10)/J10) -> 0.86666667
A11: Craft attachment | B11: =COUNTIFS(MASTER!$B:$B,$A11) -> 42 | C11: =COUNTIFS(MASTER!$B:$B,$A11,MASTER!$H:$H,C$4) -> 31 | D11: =COUNTIFS(MASTER!$B:$B,$A11,MASTER!$H:$H,D$4) -> 0 | E11: =COUNTIFS(MASTER!$B:$B,$A11,MASTER!$H:$H,E$4) -> 5 | F11: =COUNTIFS(MASTER!$B:$B,$A11,MASTER!$H:$H,F$4) -> 0 | G11: =COUNTIFS(MASTER!$B:$B,$A11,MASTER!$H:$H,G$4) -> 0 | H11: =COUNTIFS(MASTER!$B:$B,$A11,MASTER!$H:$H,H$4) -> 6 | I11: =COUNTIFS(MASTER!$B:$B,$A11,MASTER!$H:$H,I$4) -> 0 | J11: =C11+D11+E11+F11 -> 36 | K11: =IF(J11=0,0,C11/J11) -> 0.86111111 | L11: =IF(J11=0,0,(C11+D11)/J11) -> 0.86111111
A12: Instructor site | B12: =COUNTIFS(MASTER!$B:$B,$A12) -> 16 | C12: =COUNTIFS(MASTER!$B:$B,$A12,MASTER!$H:$H,C$4) -> 14 | D12: =COUNTIFS(MASTER!$B:$B,$A12,MASTER!$H:$H,D$4) -> 0 | E12: =COUNTIFS(MASTER!$B:$B,$A12,MASTER!$H:$H,E$4) -> 0 | F12: =COUNTIFS(MASTER!$B:$B,$A12,MASTER!$H:$H,F$4) -> 0 | G12: =COUNTIFS(MASTER!$B:$B,$A12,MASTER!$H:$H,G$4) -> 0 | H12: =COUNTIFS(MASTER!$B:$B,$A12,MASTER!$H:$H,H$4) -> 2 | I12: =COUNTIFS(MASTER!$B:$B,$A12,MASTER!$H:$H,I$4) -> 0 | J12: =C12+D12+E12+F12 -> 14 | K12: =IF(J12=0,0,C12/J12) -> 1 | L12: =IF(J12=0,0,(C12+D12)/J12) -> 1
A13: Other repo | B13: =COUNTIFS(MASTER!$B:$B,$A13) -> 2 | C13: =COUNTIFS(MASTER!$B:$B,$A13,MASTER!$H:$H,C$4) -> 1 | D13: =COUNTIFS(MASTER!$B:$B,$A13,MASTER!$H:$H,D$4) -> 0 | E13: =COUNTIFS(MASTER!$B:$B,$A13,MASTER!$H:$H,E$4) -> 1 | F13: =COUNTIFS(MASTER!$B:$B,$A13,MASTER!$H:$H,F$4) -> 0 | G13: =COUNTIFS(MASTER!$B:$B,$A13,MASTER!$H:$H,G$4) -> 0 | H13: =COUNTIFS(MASTER!$B:$B,$A13,MASTER!$H:$H,H$4) -> 0 | I13: =COUNTIFS(MASTER!$B:$B,$A13,MASTER!$H:$H,I$4) -> 0 | J13: =C13+D13+E13+F13 -> 2 | K13: =IF(J13=0,0,C13/J13) -> 0.5 | L13: =IF(J13=0,0,(C13+D13)/J13) -> 0.5
A14: TOTAL | B14: =SUM(B5:B13) -> 937 | C14: =SUM(C5:C13) -> 410 | D14: =SUM(D5:D13) -> 119 | E14: =SUM(E5:E13) -> 32 | F14: =SUM(F5:F13) -> 0 | G14: =SUM(G5:G13) -> 94 | H14: =SUM(H5:H13) -> 164 | I14: =SUM(I5:I13) -> 118 | J14: =SUM(J5:J13) -> 561 | K14: =IF(J14=0,0,C14/J14) -> 0.73083779 | L14: =IF(J14=0,0,(C14+D14)/J14) -> 0.942959
A17: Work still to do (Action status)
A19: Source | B19: To do | C19: Needs your decision | D19: Done | E19: Not needed
A20: Course repo file | B20: =COUNTIFS(MASTER!$B:$B,$A20,MASTER!$O:$O,B$19) -> 31 | C20: =COUNTIFS(MASTER!$B:$B,$A20,MASTER!$O:$O,C$19) -> 0 | D20: =COUNTIFS(MASTER!$B:$B,$A20,MASTER!$O:$O,D$19) -> 225 | E20: =COUNTIFS(MASTER!$B:$B,$A20,MASTER!$O:$O,E$19) -> 208
A21: LangChain docs | B21: =COUNTIFS(MASTER!$B:$B,$A21,MASTER!$O:$O,B$19) -> 11 | C21: =COUNTIFS(MASTER!$B:$B,$A21,MASTER!$O:$O,C$19) -> 0 | D21: =COUNTIFS(MASTER!$B:$B,$A21,MASTER!$O:$O,D$19) -> 39 | E21: =COUNTIFS(MASTER!$B:$B,$A21,MASTER!$O:$O,E$19) -> 146
A22: MCP docs | B22: =COUNTIFS(MASTER!$B:$B,$A22,MASTER!$O:$O,B$19) -> 20 | C22: =COUNTIFS(MASTER!$B:$B,$A22,MASTER!$O:$O,C$19) -> 31 | D22: =COUNTIFS(MASTER!$B:$B,$A22,MASTER!$O:$O,D$19) -> 48 | E22: =COUNTIFS(MASTER!$B:$B,$A22,MASTER!$O:$O,E$19) -> 1
A23: Pydantic docs | B23: =COUNTIFS(MASTER!$B:$B,$A23,MASTER!$O:$O,B$19) -> 36 | C23: =COUNTIFS(MASTER!$B:$B,$A23,MASTER!$O:$O,C$19) -> 1 | D23: =COUNTIFS(MASTER!$B:$B,$A23,MASTER!$O:$O,D$19) -> 13 | E23: =COUNTIFS(MASTER!$B:$B,$A23,MASTER!$O:$O,E$19) -> 6
A24: Meridian slides | B24: =COUNTIFS(MASTER!$B:$B,$A24,MASTER!$O:$O,B$19) -> 13 | C24: =COUNTIFS(MASTER!$B:$B,$A24,MASTER!$O:$O,C$19) -> 0 | D24: =COUNTIFS(MASTER!$B:$B,$A24,MASTER!$O:$O,D$19) -> 26 | E24: =COUNTIFS(MASTER!$B:$B,$A24,MASTER!$O:$O,E$19) -> 1
A25: Craft page | B25: =COUNTIFS(MASTER!$B:$B,$A25,MASTER!$O:$O,B$19) -> 0 | C25: =COUNTIFS(MASTER!$B:$B,$A25,MASTER!$O:$O,C$19) -> 2 | D25: =COUNTIFS(MASTER!$B:$B,$A25,MASTER!$O:$O,D$19) -> 13 | E25: =COUNTIFS(MASTER!$B:$B,$A25,MASTER!$O:$O,E$19) -> 6
A26: Craft attachment | B26: =COUNTIFS(MASTER!$B:$B,$A26,MASTER!$O:$O,B$19) -> 5 | C26: =COUNTIFS(MASTER!$B:$B,$A26,MASTER!$O:$O,C$19) -> 0 | D26: =COUNTIFS(MASTER!$B:$B,$A26,MASTER!$O:$O,D$19) -> 31 | E26: =COUNTIFS(MASTER!$B:$B,$A26,MASTER!$O:$O,E$19) -> 6
A27: Instructor site | B27: =COUNTIFS(MASTER!$B:$B,$A27,MASTER!$O:$O,B$19) -> 0 | C27: =COUNTIFS(MASTER!$B:$B,$A27,MASTER!$O:$O,C$19) -> 0 | D27: =COUNTIFS(MASTER!$B:$B,$A27,MASTER!$O:$O,D$19) -> 14 | E27: =COUNTIFS(MASTER!$B:$B,$A27,MASTER!$O:$O,E$19) -> 2
A28: Other repo | B28: =COUNTIFS(MASTER!$B:$B,$A28,MASTER!$O:$O,B$19) -> 0 | C28: =COUNTIFS(MASTER!$B:$B,$A28,MASTER!$O:$O,C$19) -> 1 | D28: =COUNTIFS(MASTER!$B:$B,$A28,MASTER!$O:$O,D$19) -> 1 | E28: =COUNTIFS(MASTER!$B:$B,$A28,MASTER!$O:$O,E$19) -> 0
A29: TOTAL | B29: =SUM(B20:B28) -> 116 | C29: =SUM(C20:C28) -> 35 | D29: =SUM(D20:D28) -> 410 | E29: =SUM(E20:E28) -> 376

Sheet MASTER
A1: ID | B1: Source | C1: Group | D1: Item | E1: Path or URL | F1: What it teaches | G1: Read status | H1: Concept covered? | I1: Overlap score | J1: Method | K1: Where covered (book:chapter and matches) | L1: Missing concepts (evidence) | M1: Priority | N1: Action needed | O1: Action status | P1: Last checked | Q1: Notes
A2: R-001 | B2: Course repo file | C2: (repo root) | D2: .gitattributes | E2: .gitattributes | F2: .gitattributes | G2: Ignored | H2: No teaching content | J2: Measured: shared terms with the books | M2: Medium | N2: None | O2: Not needed | P2: 2026-10-31 | Q2: lock file, log, config or archive
A3: R-002 | B3: Course repo file | C3: .github | D3: path-audit.yml | E3: .github/workflows/path-audit.yml | F3: Fails a push / PR that would break `git clone` or `git pull` for students on Windows, macOS or Linux | G3: Read properly | H3: No teaching content | J3: Measured: shared terms with the books | M3: Medium | N3: None | O3: Not needed | P3: 2026-10-31 | Q3: too little text to measure
A4: R-003 | B4: Course repo file | C4: (repo root) | D4: .gitignore | E4: .gitignore | F4: .gitignore | G4: Ignored | H4: No teaching content | J4: Measured: shared terms with the books | M4: Medium | N4: None | O4: Not needed | P4: 2026-10-31 | Q4: lock file, log, config or archive
A5: R-004 | B5: Course repo file | C5: (repo root) | D5: COLAB_NOTEBOOKS.md | E5: COLAB_NOTEBOOKS.md | F5: 📓 Live Colab Notebooks — Full Index | G5: Read properly | H5: Covered | I5: 1 | J5: Measured: shared terms with the books | K5: agentic-ai:ch5 (4), agentic-ai:ch10 (3), agentic-ai:ch12 (3) | M5: Medium | N5: None | O5: Done | P5: 2026-10-31
A6: R-005 | B6: Course repo file | C6: Complete MCP | D6: Commands.txt | E6: Complete MCP/Commands.txt | F6: install uv if you don't have it | G6: Looked through | H6: No teaching content | J6: Measured: shared terms with the books | M6: Medium | N6: None | O6: Not needed | P6: 2026-10-31 | Q6: too little text to measure
A7: R-006 | B7: Course repo file | C7: Complete MCP | D7: README.md | E7: Complete MCP/MCP-Precoded/README.md | F7: Building Your First MCP Server — RecipeBox, Two Ways | G7: Looked through | H7: Covered | I7: 0.84615385 | J7: Measured: shared terms with the books | K7: agentic-ai:ch14 (6), agentic-ai:ch11 (6), agentic-ai:ch16 (4) | L7: part4_building_first_server_notebook, stdio_server | M7: Medium | N7: None | O7: Done | P7: 2026-10-31
A8: R-007 | B8: Course repo file | C8: Complete MCP | D8: recipebox_fastmcp.py | E8: Complete MCP/MCP-Precoded/recipebox_fastmcp.py | F8: RecipeBox -- the EXACT same server as recipebox_lowlevel.py, rebuilt with | G8: Looked through | H8: Covered | I8: 1 | J8: Measured: shared terms with the books | K8: agentic-ai:ch14 (10), agentic-ai:ch11 (4), agentic-ai:ch16 (3) | M8: Medium | N8: None | O8: Done | P8: 2026-10-31
A9: R-008 | B9: Course repo file | C9: Complete MCP | D9: recipebox_lowlevel.py | E9: Complete MCP/MCP-Precoded/recipebox_lowlevel.py | F9: RecipeBox -- built with the RAW, low-level official `mcp` SDK. | G9: Looked through | H9: Covered | I9: 0.86666667 | J9: Measured: shared terms with the books | K9: agentic-ai:ch14 (11), agentic-ai:ch16 (6), agentic-ai:ch11 (6) | L9: create_initialization_options, stdio_server | M9: Medium | N9: None | O9: Done | P9: 2026-10-31
A10: R-009 | B10: Course repo file | C10: Complete MCP | D10: .gitignore | E10: Complete MCP/McpWarmup/.gitignore | F10: .gitignore | G10: Ignored | H10: No teaching content | J10: Measured: shared terms with the books | M10: Medium | N10: None | O10: Not needed | P10: 2026-10-31 | Q10: lock file, log, config or archive
A11: R-010 | B11: Course repo file | C11: Complete MCP | D11: .python-version | E11: Complete MCP/McpWarmup/.python-version | F11: .python-version | G11: Ignored | H11: No teaching content | J11: Measured: shared terms with the books | M11: Medium | N11: None | O11: Not needed | P11: 2026-10-31 | Q11: lock file, log, config or archive
A12: R-011 | B12: Course repo file | C12: Complete MCP | D12: README.md | E12: Complete MCP/McpWarmup/README.md | F12: README.md | G12: Looked through | H12: No teaching content | J12: Measured: shared terms with the books | M12: Medium | N12: None | O12: Not needed | P12: 2026-10-31 | Q12: too little text to measure
A13: R-012 | B13: Course repo file | C13: Complete MCP | D13: mcp_server_with_primitives.py | E13: Complete MCP/McpWarmup/mcp_server_with_primitives.py | F13: mcp_server_with_primitives.py | G13: Looked through | H13: Covered | I13: 1 | J13: Measured: shared terms with the books | K13: agentic-ai:ch12 (6) | M13: Medium | N13: None | O13: Done | P13: 2026-10-31
A14: R-013 | B14: Course repo file | C14: Complete MCP | D14: pyproject.toml | E14: Complete MCP/McpWarmup/pyproject.toml | F14: pyproject.toml | G14: Ignored | H14: No teaching content | J14: Measured: shared terms with the books | M14: Medium | N14: None | O14: Not needed | P14: 2026-10-31 | Q14: lock file, log, config or archive
A15: R-014 | B15: Course repo file | C15: Complete MCP | D15: server.py | E15: Complete MCP/McpWarmup/server.py | F15: server.py | G15: Looked through | H15: No teaching content | J15: Measured: shared terms with the books | K15: agentic-ai:ch11 (2), agentic-ai:ch16 (2) | M15: Medium | N15: None | O15: Not needed | P15: 2026-10-31 | Q15: too little text to measure
A16: R-015 | B16: Course repo file | C16: Complete MCP | D16: server_with_auth.py | E16: Complete MCP/McpWarmup/server_with_auth.py | F16: server_with_auth.py | G16: Looked through | H16: Covered | I16: 1 | J16: Measured: shared terms with the books | K16: agentic-ai:ch16 (24), agentic-ai:ch18 (9), agentic-ai:ch11 (8) | M16: Medium | N16: None | O16: Done | P16: 2026-10-31
A17: R-016 | B17: Course repo file | C17: Complete MCP | D17: __init__.py | E17: Complete MCP/McpWarmup/src/mcp_warmup/__init__.py | F17: __init__.py | G17: Ignored | H17: No teaching content | J17: Measured: shared terms with the books | M17: Medium | N17: None | O17: Not needed | P17: 2026-10-31 | Q17: lock file, log, config or archive
A18: R-017 | B18: Course repo file | C18: Complete MCP | D18: uv.lock | E18: Complete MCP/McpWarmup/uv.lock | F18: uv.lock | G18: Ignored | H18: No teaching content | J18: Measured: shared terms with the books | M18: Medium | N18: None | O18: Not needed | P18: 2026-10-31 | Q18: lock file, log, config or archive
A19: R-018 | B19: Course repo file | C19: Complete MCP | D19: mcp-client-and-advanced.zip | E19: Complete MCP/TimeTrackProject/mcp-client-and-advanced.zip | F19: mcp-client-and-advanced.zip | G19: Ignored | H19: No teaching content | J19: Measured: shared terms with the books | K19: agentic-ai:ch15, agentic-ai:ch16 | M19: Medium | N19: None | O19: Not needed | P19: 2026-10-31 | Q19: lock file, log, config or archive
A20: R-019 | B20: Course repo file | C20: Complete MCP | D20: MCP_PROTOCOL_CHANGES_SUMMARY.txt | E20: Complete MCP/TimeTrackProject/mcp-client-and-advanced/MCP_PROTOCOL_CHANGES_SUMMARY.txt | F20: MCP_PROTOCOL_CHANGES_SUMMARY.txt | G20: Looked through | H20: Covered | I20: 1 | J20: Measured: shared terms with the books | K20: agentic-ai:ch16 (6), agentic-ai:ch17 (6), agentic-ai:ch14 (2) | M20: Medium | N20: None | O20: Done | P20: 2026-10-31
A21: R-020 | B21: Course repo file | C21: Complete MCP | D21: README.md | E21: Complete MCP/TimeTrackProject/mcp-client-and-advanced/README.md | F21: Building Your Own MCP Client — Complete, Numbered, Self-Contained | G21: Read properly | H21: Covered | I21: 0.95238095 | J21: Measured: shared terms with the books | K21: agentic-ai:ch16 (20), agentic-ai:ch17 (11), agentic-ai:ch13 (6) | L21: client_project | M21: Medium | N21: None | O21: Done | P21: 2026-10-31
A22: R-021 | B22: Course repo file | C22: Complete MCP | D22: 01_raw_client.py | E22: Complete MCP/TimeTrackProject/mcp-client-and-advanced/client/01_raw_client.py | F22: 01 -- THE RAW CLIENT | G22: Read properly | H22: Covered | I22: 1 | J22: Measured: shared terms with the books | K22: agentic-ai:ch16 (20), agentic-ai:ch15 (8), agentic-ai:ch11 (8) | M22: Medium | N22: None | O22: Done | P22: 2026-10-31
A23: R-022 | B23: Course repo file | C23: Complete MCP | D23: 02_fastmcp_client_explained.py | E23: Complete MCP/TimeTrackProject/mcp-client-and-advanced/client/02_fastmcp_client_explained.py | F23: 02 -- THE EASY CLIENT, EXPLAINED STEP BY STEP | G23: Read properly | H23: Covered | I23: 1 | J23: Measured: shared terms with the books | K23: agentic-ai:ch16 (19), agentic-ai:ch14 (13), agentic-ai:ch17 (12) | M23: Medium | N23: None | O23: Done | P23: 2026-10-31
A24: R-023 | B24: Course repo file | C24: Complete MCP | D24: 03_fastmcp_client_http.py | E24: Complete MCP/TimeTrackProject/mcp-client-and-advanced/client/03_fastmcp_client_http.py | F24: 03 -- CONNECTING TO A REAL, DEPLOYED SERVER OVER HTTP | G24: Read properly | H24: Covered | I24: 1 | J24: Measured: shared terms with the books | K24: agentic-ai:ch16 (16), agentic-ai:ch11 (10), agentic-ai:ch17 (9) | M24: Medium | N24: None | O24: Done | P24: 2026-10-31
A25: R-024 | B25: Course repo file | C25: Complete MCP | D25: 04_agent_loop.py | E25: Complete MCP/TimeTrackProject/mcp-client-and-advanced/client/04_agent_loop.py | F25: 04 -- A REAL AGENT LOOP, NO FRAMEWORK | G25: Read properly | H25: Covered | I25: 1 | J25: Measured: shared terms with the books | K25: agentic-ai:ch16 (26), agentic-ai:ch17 (10), agentic-ai:ch11 (7) | M25: Medium | N25: None | O25: Done | P25: 2026-10-31
A26: R-025 | B26: Course repo file | C26: Complete MCP | D26: 05_sampling_demo.py | E26: Complete MCP/TimeTrackProject/mcp-client-and-advanced/client/05_sampling_demo.py | F26: 05 -- SUMMARIZE_WEEK: THE SERVER CALLS AN LLM DIRECTLY | G26: Read properly | H26: Covered | I26: 1 | J26: Measured: shared terms with the books | K26: agentic-ai:ch16 (18), agentic-ai:ch17 (15), agentic-ai:ch11 (11) | M26: Medium | N26: None | O26: Done | P26: 2026-10-31
A27: R-026 | B27: Course repo file | C27: Complete MCP | D27: 06_elicitation_demo.py | E27: Complete MCP/TimeTrackProject/mcp-client-and-advanced/client/06_elicitation_demo.py | F27: 06 -- ELICITATION: THE SERVER ASKS A REAL QUESTION | G27: Read properly | H27: Covered | I27: 1 | J27: Measured: shared terms with the books | K27: agentic-ai:ch17 (17), agentic-ai:ch16 (14), agentic-ai:ch13 (8) | M27: Medium | N27: None | O27: Done | P27: 2026-10-31
A28: R-027 | B28: Course repo file | C28: Complete MCP | D28: 07_ping_and_errors.py | E28: Complete MCP/TimeTrackProject/mcp-client-and-advanced/client/07_ping_and_errors.py | F28: 07 -- PING AND A REAL ERROR | G28: Read properly | H28: Covered | I28: 1 | J28: Measured: shared terms with the books | K28: agentic-ai:ch17 (11), agentic-ai:ch16 (8), agentic-ai:ch12 (7) | M28: Medium | N28: None | O28: Done | P28: 2026-10-31
A29: R-028 | B29: Course repo file | C29: Complete MCP | D29: 08_timeout_and_cancellation.py | E29: Complete MCP/TimeTrackProject/mcp-client-and-advanced/client/08_timeout_and_cancellation.py | F29: 08 -- TIMEOUT, WHICH TRIGGERS A REAL CANCELLATION | G29: Read properly | H29: Covered | I29: 1 | J29: Measured: shared terms with the books | K29: agentic-ai:ch17 (7), agentic-ai:ch16 (7), agentic-ai:ch12 (5) | M29: Medium | N29: None | O29: Done | P29: 2026-10-31
A30: R-029 | B30: Course repo file | C30: Complete MCP | D30: 09_progress_notifications.py | E30: Complete MCP/TimeTrackProject/mcp-client-and-advanced/client/09_progress_notifications.py | F30: 09 -- PROGRESS NOTIFICATIONS, WATCHED LIVE | G30: Read properly | H30: Covered | I30: 1 | J30: Measured: shared terms with the books | K30: agentic-ai:ch17 (9), agentic-ai:ch16 (6), agentic-ai:ch18 (5) | M30: Medium | N30: None | O30: Done | P30: 2026-10-31
A31: R-030 | B31: Course repo file | C31: Complete MCP | D31: database.py | E31: Complete MCP/TimeTrackProject/mcp-client-and-advanced/database.py | F31: TimeTrack's persistence layer -- SQLite, shared by every tool in this | G31: Read properly | H31: Covered | I31: 1 | J31: Measured: shared terms with the books | K31: agentic-ai:ch16 (35), agentic-ai:ch15 (17), agentic-ai:ch17 (12) | M31: Medium | N31: None | O31: Done | P31: 2026-10-31
A32: R-031 | B32: Course repo file | C32: Complete MCP | D32: main.py | E32: Complete MCP/TimeTrackProject/mcp-client-and-advanced/main.py | F32: main.py -- the COMPLETE TimeTrack server used by every file in client/. | G32: Read properly | H32: Covered | I32: 1 | J32: Measured: shared terms with the books | K32: agentic-ai:ch16 (33), agentic-ai:ch17 (22), agentic-ai:ch15 (16) | M32: Medium | N32: None | O32: Done | P32: 2026-10-31
A33: R-032 | B33: Course repo file | C33: Complete MCP | D33: pyproject.toml | E33: Complete MCP/TimeTrackProject/mcp-client-and-advanced/pyproject.toml | F33: pyproject.toml | G33: Ignored | H33: No teaching content | J33: Measured: shared terms with the books | K33: agentic-ai:ch15, agentic-ai:ch16 | M33: Medium | N33: None | O33: Not needed | P33: 2026-10-31 | Q33: lock file, log, config or archive
A34: R-033 | B34: Course repo file | C34: Complete MCP | D34: timetrack.db | E34: Complete MCP/TimeTrackProject/mcp-client-and-advanced/timetrack.db | F34: timetrack.db | G34: Ignored | H34: No teaching content | J34: Measured: shared terms with the books | K34: agentic-ai:ch15, agentic-ai:ch16 | M34: Medium | N34: None | O34: Not needed | P34: 2026-10-31 | Q34: lock file, log, config or archive
A35: R-034 | B35: Course repo file | C35: Complete MCP | D35: uv.lock | E35: Complete MCP/TimeTrackProject/mcp-client-and-advanced/uv.lock | F35: uv.lock | G35: Ignored | H35: No teaching content | J35: Measured: shared terms with the books | K35: agentic-ai:ch15, agentic-ai:ch16 | M35: Medium | N35: None | O35: Not needed | P35: 2026-10-31 | Q35: lock file, log, config or archive
A36: R-035 | B36: Course repo file | C36: Complete MCP | D36: .python-version | E36: Complete MCP/TimeTrackProject/timetrack mcp server/.python-version | F36: .python-version | G36: Ignored | H36: No teaching content | J36: Measured: shared terms with the books | K36: agentic-ai:ch15, agentic-ai:ch16 | M36: Medium | N36: None | O36: Not needed | P36: 2026-10-31 | Q36: lock file, log, config or archive
A37: R-036 | B37: Course repo file | C37: Complete MCP | D37: README.md | E37: Complete MCP/TimeTrackProject/timetrack mcp server/README.md | F37: TimeTrack | G37: Read properly | H37: Covered | I37: 0.9375 | J37: Measured: shared terms with the books | K37: agentic-ai:ch15 (14), agentic-ai:ch16 (13), agentic-ai:ch17 (5) | L37: heading: checklist complete setup | M37: Medium | N37: None | O37: Done | P37: 2026-10-31
A38: R-037 | B38: Course repo file | C38: Complete MCP | D38: database.py | E38: Complete MCP/TimeTrackProject/timetrack mcp server/database.py | F38: TimeTrack's persistence layer -- SQLite, shared by the website and the MCP | G38: Looked through | H38: Covered | I38: 0.97297297 | J38: Measured: shared terms with the books | K38: agentic-ai:ch16 (36), agentic-ai:ch15 (17), agentic-ai:ch17 (12) | L38: execute_query | M38: Medium | N38: None | O38: Done | P38: 2026-10-31
A39: R-038 | B39: Course repo file | C39: Complete MCP | D39: dummy.py | E39: Complete MCP/TimeTrackProject/timetrack mcp server/dummy.py | F39: Dummy Calculator MCP server -- a minimal example for deploying to Horizon. | G39: Looked through | H39: Covered | J39: Measured: shared terms with the books | K39: agentic-ai:ch17 (2), agentic-ai:ch18 (2), agentic-ai:ch16 (2) | M39: Medium | N39: None | O39: Done | P39: 2026-10-31 | Q39: too little text to measure; a chapter links to it
A40: R-039 | B40: Course repo file | C40: Complete MCP | D40: main.py | E40: Complete MCP/TimeTrackProject/timetrack mcp server/main.py | F40: TimeTrack -- one running application, two front doors onto the same | G40: Looked through | H40: Covered | I40: 0.76666667 | J40: Measured: shared terms with the books | K40: agentic-ai:ch15 (21), agentic-ai:ch16 (20), agentic-ai:ch17 (4) | L40: serve_index, api_list_entries, fileresponse, api_project_summary, api_list_projects, api_get_timesheet, api_log_entry | M40: Medium | N40: None | O40: Done | P40: 2026-10-31
...

Sheet LEGEND
A1: How this sheet works
A2: One row per item | B2: Every file in the course repo, every page of the LangChain, MCP and Pydantic documentation, every Meridian slide chapter, every Craft page and attachment, every instructor site and other repo.
A3: Read status | B3: What I did with the item itself: Read properly / Read in full, Looked through, NOT READ, Ignored, Excluded by you, Skipped on purpose.
A4: Concept covered? | B4: Whether the concepts in the item are in the books. This is separate from Read status: a page can be unread but its concepts may still be in the books from class notes, and a page can be read but only partly covered.
A5: Covered | B5: At least 55% of the item's distinctive terms are in the relevant book (35% if a chapter links to it as a source).
A6: Partly covered | B6: 25% to 55% of its distinctive terms are in the books, or a chapter links to it. "Missing concepts" lists terms not found.
A7: Not covered | B7: Under 25% of its distinctive terms are in the books and no chapter links to it.
A8: No teaching content | B8: Lock files, config, images, job ads, or too little text to measure.
A9: Excluded by you | B9: Frontend material and the pages you asked me to drop.
A10: Not applicable | B10: Pages outside the LangChain book (LangGraph not started, other products, integrations, generated API reference).
A11: Overlap score | B11: Share of the item's top 40 distinctive terms found in the books. Terms are code names (functions, classes, settings) and heading phrases. Generic words are removed. The books searched depend on the topic: MCP pages against the MCP chapters (LangChain ch11 to ch18), Pydantic pages against the Pydantic book, LangChain pages against the LangChain book, Meridian against the RAG book and chapter 20.
A12: Method | B12: Measured = the term overlap above. Recorded = taken from my build notes (Craft, sites). Proxy = the repo copy of the same file was measured.
A13: Limits of the measure | B13: It finds missing names and headings, not wrong explanations. A high score means the concept is named and discussed, not that the explanation is complete. Code files score low when the book explains the idea in plain words without using the file's function names. Treat "Partly covered" as a prompt to look, not a verdict.
... A16: Sources of the documentation text | B16: MCP: github.com/modelcontextprotocol/modelcontextprotocol (docs, version 2026-07-28). Pydantic: github.com/pydantic/pydantic (docs folder, main branch, close to but not exactly the "latest" site). LangChain: github.com/langchain-ai/docs (src/oss). The page lists come from the sites' llms.txt indexes.
